{
    "registryname": "chloridizing_furnace",
    "localizedname": "氯化炉",
    "color": "776D65",
    "requires-blueprint": true,
    "parts": [
        {
            "x": -1,
            "y": 0,
            "z": 0, 
            "elements": [
                "modularmachinery:blockcasing@0",
                "modularmachinery:blockenergyinputhatch"
            ]
        },
        {
            "x": 1,
            "y": 2,
            "z": 1,
            "elements": [
                "forestry:ash_brick"
            ]
        },
        {
            "x": -2,
            "y": 0,
            "z": 0,
            "elements": [
                "immersiveengineering:stone_decoration@5"
            ]
        },
        {
            "x": 3,
            "y": 4,
            "z": 2, 
            "elements": [
                "modularmachinery:blockcasing@0",
                "modularmachinery:blockinputbus"
            ]
        },
        {
            "x": 2,
            "y": 2,
            "z": 1, 
            "elements": [
                "modularmachinery:blockcasing@0"
            ]
        },
        {
            "x": 1,
            "y": 0,
            "z": 0, 
            "elements": [
                "modularmachinery:blockcasing@0",
                "modularmachinery:blockenergyinputhatch"
            ]
        },
        {
            "x": 2,
            "y": 0,
            "z": 0,
            "elements": [
                "immersiveengineering:stone_decoration@5"
            ]
        },
        {
            "x": -3,
            "y": 3,
            "z": 1,
            "elements": [
                "immersiveengineering:stone_decoration_stairs_concrete@4"
            ]
        },
        {
            "x": -2,
            "y": 5,
            "z": 2,
            "nbt": {"slabType":"0"},
            "elements": [
                "immersiveengineering:stone_decoration_slab@5"
            ]
        },
        {
            "x": -2,
            "y": 3,
            "z": 1,
            "elements": [
                "forestry:ash_stairs@1"
            ]
        },
        {
            "x": -1,
            "y": 5,
            "z": 2,
            "nbt": {"slabType":"0"},
            "elements": [
                "immersiveengineering:stone_decoration_slab@5"
            ]
        },
        {
            "x": 2,
            "y": -1,
            "z": 0,
            "elements": [
                "libvulpes:coil0@4"
            ]
        },
        {
            "x": 0,
            "y": 5,
            "z": 2,
            "nbt": {"slabType":"0"},
            "elements": [
                "immersiveengineering:stone_decoration_slab@5"
            ]
        },
        {
            "x": -2,
            "y": 1,
            "z": 0,
            "elements": [
                "immersiveengineering:stone_decoration@5"
            ]
        },
        {
            "x": -1,
            "y": 3,
            "z": 1,
            "elements": [
                "primal:slat_iron"
            ]
        },
        {
            "x": 1,
            "y": -1,
            "z": 0,
            "elements": [
                "libvulpes:coil0@4"
            ]
        },
        {
            "x": 0,
            "y": -1,
            "z": 0,
            "elements": [
                "libvulpes:coil0@4"
            ]
        },
        {
            "x": 1,
            "y": 5,
            "z": 2,
            "nbt": {"slabType":"0"},
            "elements": [
                "immersiveengineering:stone_decoration_slab@5"
            ]
        },
        {
            "x": 0,
            "y": 3,
            "z": 1,
            "elements": [
                "primal:slat_iron"
            ]
        },
        {
            "x": -1,
            "y": 1,
            "z": 0, 
            "elements": [
                "modularmachinery:blockcasing@0"
            ]
        },
        {
            "x": 2,
            "y": 5,
            "z": 2,
            "nbt": {"slabType":"0"},
            "elements": [
                "immersiveengineering:stone_decoration_slab@5"
            ]
        },
        {
            "x": 1,
            "y": 3,
            "z": 1,
            "elements": [
                "primal:slat_iron"
            ]
        },
        {
            "x": 0,
            "y": 1,
            "z": 0, 
            "elements": [
                "modularmachinery:blockcasing@0"
            ]
        },
        {
            "x": -1,
            "y": -1,
            "z": 0,
            "elements": [
                "libvulpes:coil0@4"
            ]
        },
        {
            "x": -2,
            "y": -1,
            "z": 0,
            "elements": [
                "libvulpes:coil0@4"
            ]
        },
        {
            "x": 2,
            "y": 3,
            "z": 1,
            "elements": [
                "forestry:ash_stairs@0"
            ]
        },
        {
            "x": 1,
            "y": 1,
            "z": 0, 
            "elements": [
                "modularmachinery:blockcasing@0"
            ]
        },
        {
            "x": 3,
            "y": 3,
            "z": 1,
            "elements": [
                "immersiveengineering:stone_decoration_stairs_concrete@5"
            ]
        },
        {
            "x": 2,
            "y": 1,
            "z": 0,
            "elements": [
                "immersiveengineering:stone_decoration@5"
            ]
        },
        {
            "x": -3,
            "y": 4,
            "z": 1, 
            "elements": [
                "modularmachinery:blockcasing@0",
                "modularmachinery:blockinputbus"
            ]
        },
        {
            "x": 2,
            "y": -2,
            "z": 0,
            "elements": [
                "immersiveengineering:stone_decoration@5"
            ]
        },
        {
            "x": -2,
            "y": 2,
            "z": 0,
            "elements": [
                "immersiveengineering:stone_decoration@5"
            ]
        },
        {
            "x": 1,
            "y": -2,
            "z": 0,
            "elements": [
                "immersiveengineering:stone_decoration@5"
            ]
        },
        {
            "x": 0,
            "y": -2,
            "z": 0,
            "elements": [
                "modularmachinery:blockfluidinputhatch",
                "modularmachinery:blockfluidoutputhatch",
                "modularmachinery:blockoutputbus",
                "modularmachinery:blockcasing@0"
            ]
        },
        {
            "x": -1,
            "y": 2,
            "z": 0, 
            "elements": [
                "modularmachinery:blockcasing@0"
            ]
        },
        {
            "x": 0,
            "y": 2,
            "z": 0, 
            "elements": [
                "modularmachinery:blockcasing@0"
            ]
        },
        {
            "x": -1,
            "y": -2,
            "z": 0,
            "elements": [
                "immersiveengineering:stone_decoration@5"
            ]
        },
        {
            "x": -2,
            "y": -2,
            "z": 0,
            "elements": [
                "immersiveengineering:stone_decoration@5"
            ]
        },
        {
            "x": 1,
            "y": 2,
            "z": 0, 
            "elements": [
                "modularmachinery:blockcasing@0"
            ]
        },
        {
            "x": 3,
            "y": 4,
            "z": 1, 
            "elements": [
                "modularmachinery:blockcasing@0",
                "modularmachinery:blockinputbus"
            ]
        },
        {
            "x": 2,
            "y": 2,
            "z": 0,
            "elements": [
                "immersiveengineering:stone_decoration@5"
            ]
        },
        {
            "x": -3,
            "y": 3,
            "z": 0,
            "elements": [
                "immersiveengineering:stone_decoration_stairs_concrete@4"
            ]
        },
        {
            "x": -2,
            "y": 5,
            "z": 1,
            "nbt": {"slabType":"0"},
            "elements": [
                "immersiveengineering:stone_decoration_slab@5"
            ]
        },
        {
            "x": 2,
            "y": -3,
            "z": 0,
            "elements": [
                "immersiveengineering:stone_decoration_stairs_concrete@5"
            ]
        },
        {
            "x": -2,
            "y": 3,
            "z": 0,
            "elements": [
                "forestry:ash_stairs@3"
            ]
        },
        {
            "x": -1,
            "y": 5,
            "z": 1,
            "nbt": {"slabType":"0"},
            "elements": [
                "immersiveengineering:stone_decoration_slab@5"
            ]
        },
        {
            "x": 1,
            "y": -3,
            "z": 0,
            "elements": [
                "immersiveengineering:stone_decoration_stairs_concrete@6"
            ]
        },
        {
            "x": 0,
            "y": -3,
            "z": 0,
            "elements": [
                "immersiveengineering:stone_decoration_stairs_concrete@6"
            ]
        },
        {
            "x": 0,
            "y": 5,
            "z": 1,
            "nbt": {"slabType":"0"},
            "elements": [
                "immersiveengineering:stone_decoration_slab@5"
            ]
        },
        {
            "x": -1,
            "y": 3,
            "z": 0,
            "elements": [
                "forestry:ash_stairs@3"
            ]
        },
        {
            "x": -1,
            "y": -3,
            "z": 0,
            "elements": [
                "immersiveengineering:stone_decoration_stairs_concrete@6"
            ]
        },
        {
            "x": 1,
            "y": 5,
            "z": 1,
            "nbt": {"slabType":"0"},
            "elements": [
                "immersiveengineering:stone_decoration_slab@5"
            ]
        },
        {
            "x": 0,
            "y": 3,
            "z": 0,
            "elements": [
                "forestry:ash_stairs@3"
            ]
        },
        {
            "x": 2,
            "y": 5,
            "z": 1,
            "nbt": {"slabType":"0"},
            "elements": [
                "immersiveengineering:stone_decoration_slab@5"
            ]
        },
        {
            "x": 1,
            "y": 3,
            "z": 0,
            "elements": [
                "forestry:ash_stairs@3"
            ]
        },
        {
            "x": -2,
            "y": -3,
            "z": 0,
            "elements": [
                "immersiveengineering:stone_decoration_stairs_concrete@6"
            ]
        },
        {
            "x": 2,
            "y": 3,
            "z": 0,
            "elements": [
                "forestry:ash_stairs@3"
            ]
        },
        {
            "x": 3,
            "y": 3,
            "z": 0,
            "elements": [
                "immersiveengineering:stone_decoration_stairs_concrete@5"
            ]
        },
        {
            "x": -3,
            "y": 4,
            "z": 0, 
            "elements": [
                "modularmachinery:blockcasing@0"
            ]
        },
        {
            "x": 3,
            "y": 4,
            "z": 0, 
            "elements": [
                "modularmachinery:blockcasing@0"
            ]
        },
        {
            "x": -2,
            "y": 5,
            "z": 0,
            "nbt": {"slabType":"0"},
            "elements": [
                "immersiveengineering:stone_decoration_slab@5"
            ]
        },
        {
            "x": -1,
            "y": 5,
            "z": 0,
            "nbt": {"slabType":"0"},
            "elements": [
                "immersiveengineering:stone_decoration_slab@5"
            ]
        },
        {
            "x": 0,
            "y": 5,
            "z": 0,
            "nbt": {"slabType":"0"},
            "elements": [
                "immersiveengineering:stone_decoration_slab@5"
            ]
        },
        {
            "x": 1,
            "y": 5,
            "z": 0,
            "nbt": {"slabType":"0"},
            "elements": [
                "immersiveengineering:stone_decoration_slab@5"
            ]
        },
        {
            "x": 2,
            "y": 5,
            "z": 0,
            "nbt": {"slabType":"0"},
            "elements": [
                "immersiveengineering:stone_decoration_slab@5"
            ]
        },
        {
            "x": -2,
            "y": -3,
            "z": 4,
            "elements": [
                "immersiveengineering:stone_decoration_stairs_concrete@7"
            ]
        },
        {
            "x": -1,
            "y": -3,
            "z": 4,
            "elements": [
                "immersiveengineering:stone_decoration_stairs_concrete@7"
            ]
        },
        {
            "x": 0,
            "y": -3,
            "z": 4,
            "elements": [
                "immersiveengineering:stone_decoration_stairs_concrete@7"
            ]
        },
        {
            "x": 1,
            "y": -3,
            "z": 4,
            "elements": [
                "immersiveengineering:stone_decoration_stairs_concrete@7"
            ]
        },
        {
            "x": 2,
            "y": -3,
            "z": 4,
            "elements": [
                "immersiveengineering:stone_decoration_stairs_concrete@5"
            ]
        },
        {
            "x": -2,
            "y": -2,
            "z": 4,
            "elements": [
                "immersiveengineering:stone_decoration@5"
            ]
        },
        {
            "x": -1,
            "y": -2,
            "z": 4,
            "elements": [
                "immersiveengineering:stone_decoration@5"
            ]
        },
        {
            "x": -1,
            "y": -4,
            "z": 3,
            "elements": [
                "immersiveengineering:stone_decoration_stairs_concrete@7"
            ]
        },
        {
            "x": 0,
            "y": -2,
            "z": 4, 
            "elements": [
                "modularmachinery:blockfluidinputhatch",
                "modularmachinery:blockfluidoutputhatch",
                "modularmachinery:blockoutputbus",
                "modularmachinery:blockcasing@0"
            ]
        },
        {
            "x": 0,
            "y": -4,
            "z": 3,
            "elements": [
                "immersiveengineering:stone_decoration_stairs_concrete@7"
            ]
        },
        {
            "x": 1,
            "y": -2,
            "z": 4,
            "elements": [
                "immersiveengineering:stone_decoration@5"
            ]
        },
        {
            "x": 2,
            "y": -2,
            "z": 4,
            "elements": [
                "immersiveengineering:stone_decoration@5"
            ]
        },
        {
            "x": 1,
            "y": -4,
            "z": 3,
            "elements": [
                "immersiveengineering:stone_decoration_stairs_concrete@7"
            ]
        },
        {
            "x": -2,
            "y": -1,
            "z": 4,
            "elements": [
                "libvulpes:coil0@4"
            ]
        },
        {
            "x": -2,
            "y": -3,
            "z": 3,
            "elements": [
                "immersiveengineering:stone_decoration_stairs_concrete@4"
            ]
        },
        {
            "x": -1,
            "y": -1,
            "z": 4,
            "elements": [
                "libvulpes:coil0@4"
            ]
        },
        {
            "x": -1,
            "y": -3,
            "z": 3,
            "elements": [
                "forestry:ash_brick"
            ]
        },
        {
            "x": 0,
            "y": -1,
            "z": 4,
            "elements": [
                "libvulpes:coil0@4"
            ]
        },
        {
            "x": 0,
            "y": -3,
            "z": 3,
            "elements": [
                "forestry:ash_brick"
            ]
        },
        {
            "x": 1,
            "y": -1,
            "z": 4,
            "elements": [
                "libvulpes:coil0@4"
            ]
        },
        {
            "x": 2,
            "y": -1,
            "z": 4,
            "elements": [
                "libvulpes:coil0@4"
            ]
        },
        {
            "x": 1,
            "y": -3,
            "z": 3,
            "elements": [
                "forestry:ash_brick"
            ]
        },
        {
            "x": 2,
            "y": -3,
            "z": 3,
            "elements": [
                "immersiveengineering:stone_decoration_stairs_concrete@5"
            ]
        },
        {
            "x": -2,
            "y": 0,
            "z": 4,
            "elements": [
                "immersiveengineering:stone_decoration@5"
            ]
        },
        {
            "x": -2,
            "y": -2,
            "z": 3,
            "elements": [
                "immersiveengineering:stone_decoration@5"
            ]
        },
        {
            "x": -1,
            "y": 0,
            "z": 4, 
            "elements": [
                "modularmachinery:blockcasing@0",
                "modularmachinery:blockenergyinputhatch"
            ]
        },
        {
            "x": -1,
            "y": -2,
            "z": 3,
            "elements": [
                "forestry:ash_brick"
            ]
        },
        {
            "x": 0,
            "y": 0,
            "z": 4,
            "elements": [
                "modularmachinery:blockcasing@0",
                "modularmachinery:blockenergyinputhatch"
            ]
        },
        {
            "x": -1,
            "y": -4,
            "z": 2,
            "elements": [
                "immersiveengineering:stone_decoration_stairs_concrete@4"
            ]
        },
        {
            "x": 1,
            "y": 0,
            "z": 4, 
            "elements": [
                "modularmachinery:blockcasing@0",
                "modularmachinery:blockenergyinputhatch"
            ]
        },
        {
            "x": 0,
            "y": -4,
            "z": 2,
            "elements": [
                "immersiveengineering:stone_decoration@5"
            ]
        },
        {
            "x": 2,
            "y": 0,
            "z": 4,
            "elements": [
                "immersiveengineering:stone_decoration@5"
            ]
        },
        {
            "x": 1,
            "y": -2,
            "z": 3,
            "elements": [
                "forestry:ash_brick"
            ]
        },
        {
            "x": 2,
            "y": -2,
            "z": 3,
            "elements": [
                "immersiveengineering:stone_decoration@5"
            ]
        },
        {
            "x": 1,
            "y": -4,
            "z": 2,
            "elements": [
                "immersiveengineering:stone_decoration_stairs_concrete@5"
            ]
        },
        {
            "x": -3,
            "y": 3,
            "z": 5,
            "elements": [
                "immersiveengineering:stone_decoration_stairs_concrete@4"
            ]
        },
        {
            "x": -2,
            "y": 3,
            "z": 5,
            "elements": [
                "immersiveengineering:stone_decoration_stairs_concrete@7"
            ]
        },
        {
            "x": -2,
            "y": 1,
            "z": 4,
            "elements": [
                "immersiveengineering:stone_decoration@5"
            ]
        },
        {
            "x": -1,
            "y": 3,
            "z": 5,
            "elements": [
                "immersiveengineering:stone_decoration_stairs_concrete@7"
            ]
        },
        {
            "x": 0,
            "y": 3,
            "z": 5,
            "elements": [
                "immersiveengineering:stone_decoration_stairs_concrete@7"
            ]
        },
        {
            "x": -2,
            "y": -1,
            "z": 3,
            "elements": [
                "libvulpes:coil0@4"
            ]
        },
        {
            "x": -1,
            "y": 1,
            "z": 4, 
            "elements": [
                "modularmachinery:blockcasing@0"
            ]
        },
        {
            "x": 1,
            "y": 3,
            "z": 5,
            "elements": [
                "immersiveengineering:stone_decoration_stairs_concrete@7"
            ]
        },
        {
            "x": 0,
            "y": 1,
            "z": 4, 
            "elements": [
                "modularmachinery:blockcasing@0"
            ]
        },
        {
            "x": -2,
            "y": -3,
            "z": 2,
            "elements": [
                "immersiveengineering:stone_decoration_stairs_concrete@4"
            ]
        },
        {
            "x": -1,
            "y": -1,
            "z": 3,
            "elements": [
                "forestry:ash_brick"
            ]
        },
        {
            "x": -1,
            "y": -3,
            "z": 2,
            "elements": [
                "forestry:ash_brick"
            ]
        },
        {
            "x": 2,
            "y": 3,
            "z": 5,
            "elements": [
                "immersiveengineering:stone_decoration_stairs_concrete@7"
            ]
        },
        {
            "x": 1,
            "y": 1,
            "z": 4, 
            "elements": [
                "modularmachinery:blockcasing@0"
            ]
        },
        {
            "x": 0,
            "y": -3,
            "z": 2,
            "elements": [
                "forestry:ash_brick"
            ]
        },
        {
            "x": 3,
            "y": 3,
            "z": 5,
            "elements": [
                "immersiveengineering:stone_decoration_stairs_concrete@7"
            ]
        },
        {
            "x": 2,
            "y": 1,
            "z": 4,
            "elements": [
                "immersiveengineering:stone_decoration@5"
            ]
        },
        {
            "x": 1,
            "y": -1,
            "z": 3,
            "elements": [
                "forestry:ash_brick"
            ]
        },
        {
            "x": 2,
            "y": -1,
            "z": 3,
            "elements": [
                "libvulpes:coil0@4"
            ]
        },
        {
            "x": 1,
            "y": -3,
            "z": 2,
            "elements": [
                "forestry:ash_brick"
            ]
        },
        {
            "x": 2,
            "y": -3,
            "z": 2,
            "elements": [
                "immersiveengineering:stone_decoration_stairs_concrete@5"
            ]
        },
        {
            "x": -3,
            "y": 4,
            "z": 5, 
            "elements": [
                "modularmachinery:blockcasing@0"
            ]
        },
        {
            "x": -2,
            "y": 4,
            "z": 5, 
            "elements": [
                "modularmachinery:blockcasing@0"
            ]
        },
        {
            "x": -2,
            "y": 2,
            "z": 4,
            "elements": [
                "immersiveengineering:stone_decoration@5"
            ]
        },
        {
            "x": -1,
            "y": 4,
            "z": 5, 
            "elements": [
                "modularmachinery:blockcasing@0",
                "modularmachinery:blockinputbus"
            ]
        },
        {
            "x": 0,
            "y": 4,
            "z": 5, 
            "elements": [
                "modularmachinery:blockcasing@0",
                "modularmachinery:blockinputbus"
            ]
        },
        {
            "x": -2,
            "y": 0,
            "z": 3, 
            "elements": [
                "modularmachinery:blockcasing@0",
                "modularmachinery:blockenergyinputhatch"
            ]
        },
        {
            "x": -1,
            "y": 2,
            "z": 4, 
            "elements": [
                "modularmachinery:blockcasing@0"
            ]
        },
        {
            "x": 3,
            "y": 4,
            "z": -1, 
            "elements": [
                "modularmachinery:blockcasing@0"
            ]
        },
        {
            "x": 1,
            "y": 4,
            "z": 5, 
            "elements": [
                "modularmachinery:blockcasing@0",
                "modularmachinery:blockinputbus"
            ]
        },
        {
            "x": 0,
            "y": 2,
            "z": 4, 
            "elements": [
                "modularmachinery:blockcasing@0"
            ]
        },
        {
            "x": -2,
            "y": -2,
            "z": 2, 
            "elements": [
                "modularmachinery:blockfluidinputhatch",
                "modularmachinery:blockfluidoutputhatch",
                "modularmachinery:blockoutputbus",
                "modularmachinery:blockcasing@0"
            ]
        },
        {
            "x": -1,
            "y": 0,
            "z": 3,
            "elements": [
                "forestry:ash_brick"
            ]
        },
        {
            "x": 2,
            "y": 4,
            "z": -1, 
            "elements": [
                "modularmachinery:blockcasing@0"
            ]
        },
        {
            "x": 1,
            "y": 4,
            "z": -1, 
            "elements": [
                "modularmachinery:blockcasing@0",
                "modularmachinery:blockinputbus"
            ]
        },
        {
            "x": 2,
            "y": 4,
            "z": 5, 
            "elements": [
                "modularmachinery:blockcasing@0"
            ]
        },
        {
            "x": 1,
            "y": 2,
            "z": 4, 
            "elements": [
                "modularmachinery:blockcasing@0"
            ]
        },
        {
            "x": -1,
            "y": -4,
            "z": 1,
            "elements": [
                "immersiveengineering:stone_decoration_stairs_concrete@6"
            ]
        },
        {
            "x": 0,
            "y": 4,
            "z": -1,
            "elements": [
                "modularmachinery:blockcasing@0",
                "modularmachinery:blockinputbus"
            ]
        },
        {
            "x": 3,
            "y": 4,
            "z": 5, 
            "elements": [
                "modularmachinery:blockcasing@0"
            ]
        },
        {
            "x": 2,
            "y": 2,
            "z": 4,
            "elements": [
                "immersiveengineering:stone_decoration@5"
            ]
        },
        {
            "x": 1,
            "y": 0,
            "z": 3,
            "elements": [
                "forestry:ash_brick"
            ]
        },
        {
            "x": 0,
            "y": -4,
            "z": 1,
            "elements": [
                "immersiveengineering:stone_decoration_stairs_concrete@6"
            ]
        },
        {
            "x": -1,
            "y": 4,
            "z": -1, 
            "elements": [
                "modularmachinery:blockcasing@0",
                "modularmachinery:blockinputbus"
            ]
        },
        {
            "x": 2,
            "y": 0,
            "z": 3, 
            "elements": [
                "modularmachinery:blockcasing@0",
                "modularmachinery:blockenergyinputhatch"
            ]
        },
        {
            "x": -2,
            "y": 4,
            "z": -1, 
            "elements": [
                "modularmachinery:blockcasing@0"
            ]
        },
        {
            "x": 2,
            "y": -2,
            "z": 2, 
            "elements": [
                "modularmachinery:blockfluidinputhatch",
                "modularmachinery:blockfluidoutputhatch",
                "modularmachinery:blockoutputbus",
                "modularmachinery:blockcasing@0"
            ]
        },
        {
            "x": 1,
            "y": -4,
            "z": 1,
            "elements": [
                "immersiveengineering:stone_decoration_stairs_concrete@5"
            ]
        },
        {
            "x": -3,
            "y": 4,
            "z": -1, 
            "elements": [
                "modularmachinery:blockcasing@0"
            ]
        },
        {
            "x": -3,
            "y": 3,
            "z": 4,
            "elements": [
                "immersiveengineering:stone_decoration_stairs_concrete@4"
            ]
        },
        {
            "x": -2,
            "y": 3,
            "z": 4,
            "elements": [
                "forestry:ash_stairs@2"
            ]
        },
        {
            "x": -2,
            "y": 1,
            "z": 3, 
            "elements": [
                "modularmachinery:blockcasing@0"
            ]
        },
        {
            "x": -1,
            "y": 3,
            "z": 4,
            "elements": [
                "forestry:ash_stairs@2"
            ]
        },
        {
            "x": 3,
            "y": 3,
            "z": -1,
            "elements": [
                "immersiveengineering:stone_decoration_stairs_concrete@5"
            ]
        },
        {
            "x": 0,
            "y": 3,
            "z": 4,
            "elements": [
                "forestry:ash_stairs@2"
            ]
        },
        {
            "x": -2,
            "y": -1,
            "z": 2,
            "elements": [
                "libvulpes:coil0@4"
            ]
        },
        {
            "x": -1,
            "y": 1,
            "z": 3,
            "elements": [
                "forestry:ash_brick"
            ]
        },
        {
            "x": 2,
            "y": 3,
            "z": -1,
            "elements": [
                "immersiveengineering:stone_decoration_stairs_concrete@6"
            ]
        },
        {
            "x": 1,
            "y": 3,
            "z": 4,
            "elements": [
                "forestry:ash_stairs@2"
            ]
        },
        {
            "x": 1,
            "y": 3,
            "z": -1,
            "elements": [
                "immersiveengineering:stone_decoration_stairs_concrete@6"
            ]
        },
        {
            "x": -2,
            "y": -3,
            "z": 1,
            "elements": [
                "immersiveengineering:stone_decoration_stairs_concrete@4"
            ]
        },
        {
            "x": -1,
            "y": -3,
            "z": 1,
            "elements": [
                "forestry:ash_brick"
            ]
        },
        {
            "x": 0,
            "y": 3,
            "z": -1,
            "elements": [
                "immersiveengineering:stone_decoration_stairs_concrete@6"
            ]
        },
        {
            "x": 2,
            "y": 3,
            "z": 4,
            "elements": [
                "forestry:ash_stairs@2"
            ]
        },
        {
            "x": 1,
            "y": 1,
            "z": 3,
            "elements": [
                "forestry:ash_brick"
            ]
        },
        {
            "x": 0,
            "y": -3,
            "z": 1,
            "elements": [
                "forestry:ash_brick"
            ]
        },
        {
            "x": -1,
            "y": 3,
            "z": -1,
            "elements": [
                "immersiveengineering:stone_decoration_stairs_concrete@6"
            ]
        },
        {
            "x": 3,
            "y": 3,
            "z": 4,
            "elements": [
                "immersiveengineering:stone_decoration_stairs_concrete@5"
            ]
        },
        {
            "x": 2,
            "y": 1,
            "z": 3, 
            "elements": [
                "modularmachinery:blockcasing@0"
            ]
        },
        {
            "x": -2,
            "y": 3,
            "z": -1,
            "elements": [
                "immersiveengineering:stone_decoration_stairs_concrete@6"
            ]
        },
        {
            "x": 2,
            "y": -1,
            "z": 2,
            "elements": [
                "libvulpes:coil0@4"
            ]
        },
        {
            "x": 1,
            "y": -3,
            "z": 1,
            "elements": [
                "forestry:ash_brick"
            ]
        },
        {
            "x": -3,
            "y": 3,
            "z": -1,
            "elements": [
                "immersiveengineering:stone_decoration_stairs_concrete@4"
            ]
        },
        {
            "x": 2,
            "y": -3,
            "z": 1,
            "elements": [
                "immersiveengineering:stone_decoration_stairs_concrete@5"
            ]
        },
        {
            "x": -3,
            "y": 4,
            "z": 4, 
            "elements": [
                "modularmachinery:blockcasing@0"
            ]
        },
        {
            "x": -2,
            "y": 2,
            "z": 3, 
            "elements": [
                "modularmachinery:blockcasing@0"
            ]
        },
        {
            "x": -2,
            "y": 0,
            "z": 2, 
            "elements": [
                "modularmachinery:blockcasing@0",
                "modularmachinery:blockenergyinputhatch"
            ]
        },
        {
            "x": -1,
            "y": 2,
            "z": 3,
            "elements": [
                "forestry:ash_brick"
            ]
        },
        {
            "x": -2,
            "y": -2,
            "z": 1,
            "elements": [
                "immersiveengineering:stone_decoration@5"
            ]
        },
        {
            "x": 1,
            "y": 2,
            "z": 3,
            "elements": [
                "forestry:ash_brick"
            ]
        },
        {
            "x": -1,
            "y": -2,
            "z": 1,
            "elements": [
                "forestry:ash_brick"
            ]
        },
        {
            "x": 3,
            "y": 4,
            "z": 4, 
            "elements": [
                "modularmachinery:blockcasing@0"
            ]
        },
        {
            "x": 2,
            "y": 2,
            "z": 3, 
            "elements": [
                "modularmachinery:blockcasing@0"
            ]
        },
        {
            "x": 2,
            "y": 0,
            "z": 2, 
            "elements": [
                "modularmachinery:blockcasing@0",
                "modularmachinery:blockenergyinputhatch"
            ]
        },
        {
            "x": 1,
            "y": -2,
            "z": 1,
            "elements": [
                "forestry:ash_brick"
            ]
        },
        {
            "x": 2,
            "y": -2,
            "z": 1,
            "elements": [
                "immersiveengineering:stone_decoration@5"
            ]
        },
        {
            "x": -3,
            "y": 3,
            "z": 3,
            "elements": [
                "immersiveengineering:stone_decoration_stairs_concrete@4"
            ]
        },
        {
            "x": -2,
            "y": 5,
            "z": 4,
            "nbt": {"slabType":"0"},
            "elements": [
                "immersiveengineering:stone_decoration_slab@5"
            ]
        },
        {
            "x": -2,
            "y": 3,
            "z": 3,
            "elements": [
                "forestry:ash_stairs@1"
            ]
        },
        {
            "x": -1,
            "y": 5,
            "z": 4,
            "nbt": {"slabType":"0"},
            "elements": [
                "immersiveengineering:stone_decoration_slab@5"
            ]
        },
        {
            "x": 0,
            "y": 5,
            "z": 4,
            "nbt": {"slabType":"0"},
            "elements": [
                "immersiveengineering:stone_decoration_slab@5"
            ]
        },
        {
            "x": -2,
            "y": 1,
            "z": 2, 
            "elements": [
                "modularmachinery:blockcasing@0"
            ]
        },
        {
            "x": -1,
            "y": 3,
            "z": 3,
            "elements": [
                "primal:slat_iron"
            ]
        },
        {
            "x": 1,
            "y": 5,
            "z": 4,
            "nbt": {"slabType":"0"},
            "elements": [
                "immersiveengineering:stone_decoration_slab@5"
            ]
        },
        {
            "x": 0,
            "y": 3,
            "z": 3,
            "elements": [
                "primal:slat_iron"
            ]
        },
        {
            "x": -2,
            "y": -1,
            "z": 1,
            "elements": [
                "libvulpes:coil0@4"
            ]
        },
        {
            "x": 2,
            "y": 5,
            "z": 4,
            "nbt": {"slabType":"0"},
            "elements": [
                "immersiveengineering:stone_decoration_slab@5"
            ]
        },
        {
            "x": 1,
            "y": 3,
            "z": 3,
            "elements": [
                "primal:slat_iron"
            ]
        },
        {
            "x": -1,
            "y": -1,
            "z": 1,
            "elements": [
                "forestry:ash_brick"
            ]
        },
        {
            "x": 2,
            "y": 3,
            "z": 3,
            "elements": [
                "forestry:ash_stairs@0"
            ]
        },
        {
            "x": 3,
            "y": 3,
            "z": 3,
            "elements": [
                "immersiveengineering:stone_decoration_stairs_concrete@5"
            ]
        },
        {
            "x": 2,
            "y": 1,
            "z": 2, 
            "elements": [
                "modularmachinery:blockcasing@0"
            ]
        },
        {
            "x": 1,
            "y": -1,
            "z": 1,
            "elements": [
                "forestry:ash_brick"
            ]
        },
        {
            "x": 2,
            "y": -1,
            "z": 1,
            "elements": [
                "libvulpes:coil0@4"
            ]
        },
        {
            "x": -3,
            "y": 4,
            "z": 3, 
            "elements": [
                "modularmachinery:blockcasing@0",
                "modularmachinery:blockinputbus"
            ]
        },
        {
            "x": -2,
            "y": 2,
            "z": 2, 
            "elements": [
                "modularmachinery:blockcasing@0"
            ]
        },
        {
            "x": -2,
            "y": 0,
            "z": 1, 
            "elements": [
                "modularmachinery:blockcasing@0",
                "modularmachinery:blockenergyinputhatch"
            ]
        },
        {
            "x": -1,
            "y": 0,
            "z": 1,
            "elements": [
                "forestry:ash_brick"
            ]
        },
        {
            "x": 3,
            "y": 4,
            "z": 3, 
            "elements": [
                "modularmachinery:blockcasing@0",
                "modularmachinery:blockinputbus"
            ]
        },
        {
            "x": 2,
            "y": 2,
            "z": 2, 
            "elements": [
                "modularmachinery:blockcasing@0"
            ]
        },
        {
            "x": 1,
            "y": 0,
            "z": 1,
            "elements": [
                "forestry:ash_brick"
            ]
        },
        {
            "x": 2,
            "y": 0,
            "z": 1, 
            "elements": [
                "modularmachinery:blockcasing@0",
                "modularmachinery:blockenergyinputhatch"
            ]
        },
        {
            "x": -3,
            "y": 3,
            "z": 2,
            "elements": [
                "immersiveengineering:stone_decoration_stairs_concrete@4"
            ]
        },
        {
            "x": -2,
            "y": 5,
            "z": 3,
            "nbt": {"slabType":"0"},
            "elements": [
                "immersiveengineering:stone_decoration_slab@5"
            ]
        },
        {
            "x": -2,
            "y": 3,
            "z": 2,
            "elements": [
                "forestry:ash_stairs@1"
            ]
        },
        {
            "x": -1,
            "y": 5,
            "z": 3,
            "nbt": {"slabType":"0"},
            "elements": [
                "immersiveengineering:stone_decoration_slab@5"
            ]
        },
        {
            "x": 0,
            "y": 5,
            "z": 3,
            "nbt": {"slabType":"0"},
            "elements": [
                "immersiveengineering:stone_decoration_slab@5"
            ]
        },
        {
            "x": -2,
            "y": 1,
            "z": 1, 
            "elements": [
                "modularmachinery:blockcasing@0"
            ]
        },
        {
            "x": -1,
            "y": 3,
            "z": 2,
            "elements": [
                "primal:slat_iron"
            ]
        },
        {
            "x": 1,
            "y": 5,
            "z": 3,
            "nbt": {"slabType":"0"},
            "elements": [
                "immersiveengineering:stone_decoration_slab@5"
            ]
        },
        {
            "x": 0,
            "y": 3,
            "z": 2,
            "elements": [
                "primal:slat_iron"
            ]
        },
        {
            "x": -1,
            "y": 1,
            "z": 1,
            "elements": [
                "forestry:ash_brick"
            ]
        },
        {
            "x": 2,
            "y": 5,
            "z": 3,
            "nbt": {"slabType":"0"},
            "elements": [
                "immersiveengineering:stone_decoration_slab@5"
            ]
        },
        {
            "x": 1,
            "y": 3,
            "z": 2,
            "elements": [
                "primal:slat_iron"
            ]
        },
        {
            "x": 2,
            "y": 3,
            "z": 2,
            "elements": [
                "forestry:ash_stairs@0"
            ]
        },
        {
            "x": 1,
            "y": 1,
            "z": 1,
            "elements": [
                "forestry:ash_brick"
            ]
        },
        {
            "x": 3,
            "y": 3,
            "z": 2,
            "elements": [
                "immersiveengineering:stone_decoration_stairs_concrete@5"
            ]
        },
        {
            "x": 2,
            "y": 1,
            "z": 1, 
            "elements": [
                "modularmachinery:blockcasing@0"
            ]
        },
        {
            "x": -3,
            "y": 4,
            "z": 2, 
            "elements": [
                "modularmachinery:blockcasing@0",
                "modularmachinery:blockinputbus"
            ]
        },
        {
            "x": -2,
            "y": 2,
            "z": 1, 
            "elements": [
                "modularmachinery:blockcasing@0"
            ]
        },
        {
            "x": -1,
            "y": 2,
            "z": 1,
            "elements": [
                "forestry:ash_brick"
            ]
        }
    ]}