{
    "registryname": "ultimate_generator",
    "localizedname": "融合发电机",
    "color": "000000",
    "requires-blueprint": true,
    "parts": [
        {
            "x": 2,
            "y": [0,1,2,3,4,5],
            "z": 2,
            "elements": [
                "astralsorcery:blockmarble@2"
            ]
        },
        {
            "x": 1,
            "y": [0,1,2,3,4,5],
            "z": 1,
            "elements": [
                "astralsorcery:blockmarble@2"
            ]
        },
        {
            "x": -1,
            "y": [0,1,2,3,4,5],
            "z": 1,
            "elements": [
                "astralsorcery:blockmarble@2"
            ]
        },
        {
            "x": -2,
            "y": [0,1,2,3,4,5],
            "z": 2,
            "elements": [
                "astralsorcery:blockmarble@2"
            ]
        },
        {
            "x": -2,
            "y": [0,1,2,3,4,5],
            "z": 4,
            "elements": [
                "astralsorcery:blockmarble@2"
            ]
        },
        {
            "x": -1,
            "y": [0,1,2,3,4,5],
            "z": 5,
            "elements": [
                "astralsorcery:blockmarble@2"
            ]
        },
        {
            "x": 2,
            "y": [0,1,2,3,4,5],
            "z": 4,
            "elements": [
                "astralsorcery:blockmarble@2"
            ]
        },
        {
            "x": 1,
            "y": [0,1,2,3,4,5],
            "z": 5,
            "elements": [
                "astralsorcery:blockmarble@2"
            ]
        },
        {
            "x": -1,
            "y": 4,
            "z": 6,
            "elements": [
                "astralsorcery:blockmarble@3"
            ]
        },
        {
            "x": 3,
            "y": 4,
            "z": 2,
            "elements": [
                "astralsorcery:blockmarble@3"
            ]
        },
        {
            "x": -3,
            "y": 0,
            "z": 0,
            "elements": [
                "bloodmagic:inversion_pillar_end@4"
            ]
        },
        {
            "x": 1,
            "y": 4,
            "z": 6,
            "elements": [
                "astralsorcery:blockmarble@3"
            ]
        },
        {
            "x": 3,
            "y": 0,
            "z": 0,
            "elements": [
                "bloodmagic:inversion_pillar_end@2"
            ]
        },
        {
            "x": 0,
            "y": 0,
            "z": 4,
            "elements": [
                "bloodmagic:blood_rune@10"
            ]
        },
        {
            "x": 3,
            "y": 4,
            "z": 6,
            "elements": [
                "bloodmagic:demon_crystal@4"
            ]
        },
        {
            "x": -3,
            "y": 1,
            "z": 0,
            "elements": [
                "bloodmagic:inversion_pillar@2"
            ]
        },
        {
            "x": 0,
            "y": 1,
            "z": 0,
            "elements": [
                "bloodmagic:blood_rune@5"
            ]
        },
        {
            "x": 3,
            "y": 1,
            "z": 0,
            "elements": [
                "bloodmagic:inversion_pillar@1"
            ]
        },
        {
            "x": -1,
            "y": 1,
            "z": 4,
            "elements": [
                "thaumcraft:pillar_arcane"
            ]
        },
        {
            "x": 0,
            "y": 1,
            "z": 4,
            "elements": [
                "thaumcraft:inlay"
            ]
        },
        {
            "x": 1,
            "y": 1,
            "z": 4,
            "elements": [
                "thaumcraft:pillar_arcane"
            ]
        },
        {
            "x": -2,
            "y": 6,
            "z": 2,
            "elements": [
                "thaumcraft:crystal_ignis"
            ]
        },
        {
            "x": -3,
            "y": 2,
            "z": 0,
            "elements": [
                "bloodmagic:inversion_pillar_end@5"
            ]
        },
        {
            "x": -2,
            "y": 4,
            "z": 1,
            "elements": [
                "astralsorcery:blockmarble@3"
            ]
        },
        {
            "x": 2,
            "y": 6,
            "z": 2,
            "elements": [
                "thaumcraft:crystal_aqua"
            ]
        },
        {
            "x": 0,
            "y": 2,
            "z": 0,
            "elements": [
                "bloodmagic:demon_pylon@0"
            ]
        },
        {
            "x": -2,
            "y": 4,
            "z": 5,
            "elements": [
                "astralsorcery:blockmarble@3"
            ]
        },
        {
            "x": 2,
            "y": 4,
            "z": 1,
            "elements": [
                "astralsorcery:blockmarble@3"
            ]
        },
        {
            "x": -3,
            "y": 0,
            "z": 3,
            "elements": [
                "modularmachinery:blockfluidinputhatch"
            ]
        },
        {
            "x": 3,
            "y": 2,
            "z": 0,
            "elements": [
                "bloodmagic:inversion_pillar_end@3"
            ]
        },
        {
            "x": -2,
            "y": 0,
            "z": 3,
            "elements": [
                "thaumcraft:stone_arcane_brick@0"
            ]
        },
        {
            "x": -1,
            "y": 0,
            "z": 3,
            "elements": [
                "bloodmagic:blood_rune@10"
            ]
        },
        {
            "x": 0,
            "y": 0,
            "z": 3,
            "elements": [
                "thaumcraft:smelter_void"
            ]
        },
        {
            "x": 2,
            "y": 4,
            "z": 5,
            "elements": [
                "astralsorcery:blockmarble@3"
            ]
        },
        {
            "x": 1,
            "y": 0,
            "z": 3,
            "elements": [
                "bloodmagic:blood_rune@10"
            ]
        },
        {
            "x": 2,
            "y": 0,
            "z": 3,
            "elements": [
                "thaumcraft:stone_arcane_brick@0"
            ]
        },
        {
            "x": 3,
            "y": 0,
            "z": 3,
            "elements": [
                "gugu-utils:aspectinputhatch"
            ]
        },
        {
            "x": -3,
            "y": 3,
            "z": 0,
            "elements": [
                "bloodmagic:demon_extras@12"
            ]
        },
        {
            "x": -3,
            "y": 1,
            "z": 3,
            "elements": [
                "astralsorcery:blockwell@0"
            ]
        },
        {
            "x": -2,
            "y": 1,
            "z": 3,
            "elements": [
                "thaumcraft:inlay"
            ]
        },
        {
            "x": 3,
            "y": 3,
            "z": 0,
            "elements": [
                "bloodmagic:demon_extras@11"
            ]
        },
        {
            "x": -1,
            "y": 1,
            "z": 3,
            "elements": [
                "thaumcraft:inlay"
            ]
        },
        {
            "x": 0,
            "y": 1,
            "z": 3,
            "elements": [
                "bloodmagic:altar@0"
            ]
        },
        {
            "x": 1,
            "y": 1,
            "z": 3,
            "elements": [
                "thaumcraft:inlay"
            ]
        },
        {
            "x": 2,
            "y": 1,
            "z": 3,
            "elements": [
                "thaumcraft:inlay"
            ]
        },
        {
            "x": 3,
            "y": 1,
            "z": 3,
            "elements": [
                "thaumcraft:vis_battery@10"
            ]
        },
        {
            "x": -3,
            "y": 4,
            "z": 0,
            "elements": [
                "bloodmagic:demon_crystal@2"
            ]
        },
        {
            "x": -1,
            "y": 6,
            "z": 1,
            "elements": [
                "thaumcraft:crystal_ignis"
            ]
        },
        {
            "x": -1,
            "y": 4,
            "z": 0,
            "elements": [
                "astralsorcery:blockmarble@3"
            ]
        },
        {
            "x": 1,
            "y": 6,
            "z": 1,
            "elements": [
                "thaumcraft:crystal_aqua"
            ]
        },
        {
            "x": 1,
            "y": 4,
            "z": 0,
            "elements": [
                "astralsorcery:blockmarble@3"
            ]
        },
        {
            "x": -3,
            "y": 4,
            "z": 4,
            "elements": [
                "astralsorcery:blockmarble@3"
            ]
        },
        {
            "x": -3,
            "y": 2,
            "z": 3,
            "elements": [
                "astralsorcery:blockmachine@0"
            ]
        },
        {
            "x": -1,
            "y": 6,
            "z": 5,
            "elements": [
                "thaumcraft:crystal_aer"
            ]
        },
        {
            "x": 3,
            "y": 4,
            "z": 0,
            "elements": [
                "bloodmagic:demon_crystal@1"
            ]
        },
        {
            "x": 1,
            "y": 6,
            "z": 5,
            "elements": [
                "thaumcraft:crystal_terra"
            ]
        },
        {
            "x": 0,
            "y": 0,
            "z": 2,
            "elements": [
                "bloodmagic:blood_rune@10"
            ]
        },
        {
            "x": 1,
            "y": 0,
            "z": 2,
            "elements": [
                "bloodmagic:blood_rune@10"
            ]
        },
        {
            "x": -1,
            "y": 0,
            "z": 2,
            "elements": [
                "bloodmagic:blood_rune@10"
            ]
        },
        {
            "x": 1,
            "y": 0,
            "z": 4,
            "elements": [
                "bloodmagic:blood_rune@10"
            ]
        },
        {
            "x": -1,
            "y": 0,
            "z": 4,
            "elements": [
                "bloodmagic:blood_rune@10"
            ]
        },
        {
            "x": -3,
            "y": 0,
            "z": 6,
            "elements": [
                "bloodmagic:inversion_pillar_end@6"
            ]
        },
        {
            "x": 3,
            "y": 4,
            "z": 4,
            "elements": [
                "astralsorcery:blockmarble@3"
            ]
        },
        {
            "x": 3,
            "y": 2,
            "z": 3,
            "elements": [
                "thaumcraft:recharge_pedestal@0"
            ]
        },
        {
            "x": 0,
            "y": 0,
            "z": 6,
            "elements": [
                "gugu-utils:sparkmanahatch"
            ]
        },
        {
            "x": 3,
            "y": 0,
            "z": 6,
            "elements": [
                "bloodmagic:inversion_pillar_end@8"
            ]
        },
        {
            "x": 0,
            "y": 3,
            "z": 3,
            "elements": [
                "botania:pylon@2"
            ]
        },
        {
            "x": -1,
            "y": 1,
            "z": 2,
            "elements": [
                "thaumcraft:pillar_arcane"
            ]
        },
        {
            "x": 0,
            "y": 1,
            "z": 2,
            "elements": [
                "thaumcraft:inlay"
            ]
        },
        {
            "x": -3,
            "y": 1,
            "z": 6,
            "elements": [
                "bloodmagic:inversion_pillar@3"
            ]
        },
        {
            "x": 1,
            "y": 1,
            "z": 2,
            "elements": [
                "thaumcraft:pillar_arcane"
            ]
        },
        {
            "x": 3,
            "y": 3,
            "z": 3,
            "elements": [
                "thaumcraft:essentia_input"
            ]
        },
        {
            "x": 0,
            "y": 3,
            "z": 6,
            "elements": [
                "botania:pylon@2"
            ]
        },
        {
            "x": 3,
            "y": 1,
            "z": 6,
            "elements": [
                "bloodmagic:inversion_pillar@4"
            ]
        },
        {
            "x": -2,
            "y": 6,
            "z": 4,
            "elements": [
                "thaumcraft:crystal_aer"
            ]
        },
        {
            "x": 0,
            "y": 4,
            "z": 3,
            "elements": [
                "modularmachinery:blockenergyoutputhatch"
            ]
        },
        {
            "x": 2,
            "y": 6,
            "z": 4,
            "elements": [
                "thaumcraft:crystal_terra"
            ]
        },
        {
            "x": 0,
            "y": 0,
            "z": 1,
            "elements": [
                "thaumcraft:stone_arcane_brick@0"
            ]
        },
        {
            "x": -3,
            "y": 2,
            "z": 6,
            "elements": [
                "bloodmagic:inversion_pillar_end@7"
            ]
        },
        {
            "x": 0,
            "y": 1,
            "z": 6,
            "elements": [
                "botanicadds:elven_altar@0"
            ]
        },
        {
            "x": 0,
            "y": 0,
            "z": 5,
            "elements": [
                "thaumcraft:stone_arcane_brick@0"
            ]
        },
        {
            "x": 3,
            "y": 2,
            "z": 6,
            "elements": [
                "bloodmagic:inversion_pillar_end@9"
            ]
        },
        {
            "x": 0,
            "y": 5,
            "z": 3,
            "elements": [
                "botanicadds:gaia_plate"
            ]
        },
        {
            "x": 0,
            "y": 1,
            "z": 1,
            "elements": [
                "thaumcraft:inlay"
            ]
        },
        {
            "x": -3,
            "y": 3,
            "z": 6,
            "elements": [
                "bloodmagic:demon_extras@13"
            ]
        },
        {
            "x": 0,
            "y": 2,
            "z": 6,
            "elements": [
                "botania:spawnerclaw"
            ]
        },
        {
            "x": 0,
            "y": 1,
            "z": 5,
            "elements": [
                "thaumcraft:inlay"
            ]
        },
        {
            "x": 3,
            "y": 3,
            "z": 6,
            "elements": [
                "bloodmagic:demon_extras@14"
            ]
        },
        {
            "x": -3,
            "y": 4,
            "z": 2,
            "elements": [
                "astralsorcery:blockmarble@3"
            ]
        },
        {
            "x": 0,
            "y": 6,
            "z": 3,
            "elements": [
                "astralsorcery:blockcelestialcollectorcrystal"
            ]
        },
        {
            "x": -3,
            "y": 4,
            "z": 6,
            "elements": [
                "bloodmagic:demon_crystal@3"
            ]
        },
        {
            "x": 2,
            "y": 3,
            "z": 1,
            "elements": [
                "botania:quartzslabelfhalf@8"
            ]
        },
        {
            "x": -2,
            "y": 3,
            "z": 5,
            "elements": [
                "botania:quartzslabredhalf@8"
            ]
        },
        {
            "x": 3,
            "y": 3,
            "z": 1,
            "elements": [
                "botania:quartzslabelfhalf@8"
            ]
        },
        {
            "x": -2,
            "y": 3,
            "z": 6,
            "elements": [
                "botania:quartzslabredhalf@8"
            ]
        },
        {
            "x": 2,
            "y": 3,
            "z": 5,
            "elements": [
                "botania:quartzslablavenderhalf@8"
            ]
        },
        {
            "x": 3,
            "y": 3,
            "z": 5,
            "elements": [
                "botania:quartzslablavenderhalf@8"
            ]
        },
        {
            "x": 2,
            "y": 3,
            "z": 6,
            "elements": [
                "botania:quartzslablavenderhalf@8"
            ]
        },
        {
            "x": -3,
            "y": 3,
            "z": 1,
            "elements": [
                "botania:quartzslabblazehalf@8"
            ]
        },
        {
            "x": -2,
            "y": 3,
            "z": 0,
            "elements": [
                "botania:quartzslabblazehalf@8"
            ]
        },
        {
            "x": -2,
            "y": 3,
            "z": 1,
            "elements": [
                "botania:quartzslabblazehalf@8"
            ]
        },
        {
            "x": 2,
            "y": 3,
            "z": 0,
            "elements": [
                "botania:quartzslabelfhalf@8"
            ]
        },
        {
            "x": -3,
            "y": 3,
            "z": 5,
            "elements": [
                "botania:quartzslabredhalf@8"
            ]
        }
    ]}